[2023-12-24T00:15:14.045+0000] {taskinstance.py:1957} INFO - Dependencies all met for dep_context=non-requeueable deps ti=<TaskInstance: extract-transform-load.load scheduled__2023-12-23T00:00:00+00:00 [queued]>
[2023-12-24T00:15:14.070+0000] {taskinstance.py:1957} INFO - Dependencies all met for dep_context=requeueable deps ti=<TaskInstance: extract-transform-load.load scheduled__2023-12-23T00:00:00+00:00 [queued]>
[2023-12-24T00:15:14.076+0000] {taskinstance.py:2171} INFO - Starting attempt 4 of 6
[2023-12-24T00:15:14.114+0000] {taskinstance.py:2192} INFO - Executing <Task(_PythonDecoratedOperator): load> on 2023-12-23 00:00:00+00:00
[2023-12-24T00:15:14.131+0000] {standard_task_runner.py:60} INFO - Started process 16110 to run task
[2023-12-24T00:15:14.140+0000] {standard_task_runner.py:87} INFO - Running: ['***', 'tasks', 'run', 'extract-transform-load', 'load', 'scheduled__2023-12-23T00:00:00+00:00', '--job-id', '112', '--raw', '--subdir', 'DAGS_FOLDER/api.py', '--cfg-path', '/tmp/tmpnm0uxuqy']
[2023-12-24T00:15:14.143+0000] {standard_task_runner.py:88} INFO - Job 112: Subtask load
[2023-12-24T00:15:14.243+0000] {task_command.py:423} INFO - Running <TaskInstance: extract-transform-load.load scheduled__2023-12-23T00:00:00+00:00 [running]> on host 1c6925ad37f2
[2023-12-24T00:15:14.835+0000] {taskinstance.py:2481} INFO - Exporting env vars: AIRFLOW_CTX_DAG_OWNER='william' AIRFLOW_CTX_DAG_ID='extract-transform-load' AIRFLOW_CTX_TASK_ID='load' AIRFLOW_CTX_EXECUTION_DATE='2023-12-23T00:00:00+00:00' AIRFLOW_CTX_TRY_NUMBER='4' AIRFLOW_CTX_DAG_RUN_ID='scheduled__2023-12-23T00:00:00+00:00'
[2023-12-24T00:15:14.841+0000] {taskinstance.py:2699} ERROR - Task failed with exception
Traceback (most recent call last):
  File "/home/airflow/.local/lib/python3.8/site-packages/airflow/models/taskinstance.py", line 433, in _execute_task
    result = execute_callable(context=context, **execute_callable_kwargs)
  File "/home/airflow/.local/lib/python3.8/site-packages/airflow/decorators/base.py", line 242, in execute
    return_value = super().execute(context)
  File "/home/airflow/.local/lib/python3.8/site-packages/airflow/operators/python.py", line 199, in execute
    return_value = self.execute_callable()
  File "/home/airflow/.local/lib/python3.8/site-packages/airflow/operators/python.py", line 216, in execute_callable
    return self.python_callable(*self.op_args, **self.op_kwargs)
  File "/opt/airflow/dags/api.py", line 36, in load
    connection = psycopg2.connect(user="postgres",
  File "/home/airflow/.local/lib/python3.8/site-packages/psycopg2/__init__.py", line 122, in connect
    conn = _connect(dsn, connection_factory=connection_factory, **kwasync)
psycopg2.OperationalError: connection to server at "127.0.0.1", port 5433 failed: Connection refused
	Is the server running on that host and accepting TCP/IP connections?

[2023-12-24T00:15:14.867+0000] {taskinstance.py:1138} INFO - Marking task as UP_FOR_RETRY. dag_id=extract-transform-load, task_id=load, execution_date=20231223T000000, start_date=20231224T001514, end_date=20231224T001514
[2023-12-24T00:15:14.888+0000] {standard_task_runner.py:107} ERROR - Failed to execute job 112 for task load (connection to server at "127.0.0.1", port 5433 failed: Connection refused
	Is the server running on that host and accepting TCP/IP connections?
; 16110)
[2023-12-24T00:15:14.977+0000] {local_task_job_runner.py:234} INFO - Task exited with return code 1
[2023-12-24T00:15:15.016+0000] {taskinstance.py:3281} INFO - 0 downstream tasks scheduled from follow-on schedule check
