[2023-12-26T01:18:25.955+0000] {taskinstance.py:1957} INFO - Dependencies all met for dep_context=non-requeueable deps ti=<TaskInstance: extract-transform-load.load scheduled__2023-12-24T00:00:00+00:00 [queued]>
[2023-12-26T01:18:25.960+0000] {taskinstance.py:1957} INFO - Dependencies all met for dep_context=requeueable deps ti=<TaskInstance: extract-transform-load.load scheduled__2023-12-24T00:00:00+00:00 [queued]>
[2023-12-26T01:18:25.961+0000] {taskinstance.py:2171} INFO - Starting attempt 5 of 6
[2023-12-26T01:18:25.966+0000] {taskinstance.py:2192} INFO - Executing <Task(_PythonDecoratedOperator): load> on 2023-12-24 00:00:00+00:00
[2023-12-26T01:18:25.970+0000] {standard_task_runner.py:60} INFO - Started process 375 to run task
[2023-12-26T01:18:25.973+0000] {standard_task_runner.py:87} INFO - Running: ['***', 'tasks', 'run', 'extract-transform-load', 'load', 'scheduled__2023-12-24T00:00:00+00:00', '--job-id', '172', '--raw', '--subdir', 'DAGS_FOLDER/api.py', '--cfg-path', '/tmp/tmpff6jefbh']
[2023-12-26T01:18:25.974+0000] {standard_task_runner.py:88} INFO - Job 172: Subtask load
[2023-12-26T01:18:26.007+0000] {task_command.py:423} INFO - Running <TaskInstance: extract-transform-load.load scheduled__2023-12-24T00:00:00+00:00 [running]> on host 023f8da17198
[2023-12-26T01:18:26.160+0000] {taskinstance.py:2481} INFO - Exporting env vars: AIRFLOW_CTX_DAG_OWNER='william' AIRFLOW_CTX_DAG_ID='extract-transform-load' AIRFLOW_CTX_TASK_ID='load' AIRFLOW_CTX_EXECUTION_DATE='2023-12-24T00:00:00+00:00' AIRFLOW_CTX_TRY_NUMBER='5' AIRFLOW_CTX_DAG_RUN_ID='scheduled__2023-12-24T00:00:00+00:00'
[2023-12-26T01:18:26.176+0000] {taskinstance.py:2699} ERROR - Task failed with exception
Traceback (most recent call last):
  File "/home/airflow/.local/lib/python3.8/site-packages/airflow/models/taskinstance.py", line 433, in _execute_task
    result = execute_callable(context=context, **execute_callable_kwargs)
  File "/home/airflow/.local/lib/python3.8/site-packages/airflow/decorators/base.py", line 242, in execute
    return_value = super().execute(context)
  File "/home/airflow/.local/lib/python3.8/site-packages/airflow/operators/python.py", line 199, in execute
    return_value = self.execute_callable()
  File "/home/airflow/.local/lib/python3.8/site-packages/airflow/operators/python.py", line 216, in execute_callable
    return self.python_callable(*self.op_args, **self.op_kwargs)
  File "/opt/airflow/dags/api.py", line 57, in load
    cursor.copy_from(f, 'sales', sep=';', )
psycopg2.errors.BadCopyFileFormat: extra data after last expected column
CONTEXT:  COPY sales, line 1: "0;B07JW9H4J1;Wayona Nylon Braided USB to Lightning Fast Charging and Data Sync Cable Compatible for ..."

[2023-12-26T01:18:26.185+0000] {taskinstance.py:1138} INFO - Marking task as UP_FOR_RETRY. dag_id=extract-transform-load, task_id=load, execution_date=20231224T000000, start_date=20231226T011825, end_date=20231226T011826
[2023-12-26T01:18:26.192+0000] {standard_task_runner.py:107} ERROR - Failed to execute job 172 for task load (extra data after last expected column
CONTEXT:  COPY sales, line 1: "0;B07JW9H4J1;Wayona Nylon Braided USB to Lightning Fast Charging and Data Sync Cable Compatible for ..."
; 375)
[2023-12-26T01:18:26.227+0000] {local_task_job_runner.py:234} INFO - Task exited with return code 1
[2023-12-26T01:18:26.240+0000] {taskinstance.py:3281} INFO - 0 downstream tasks scheduled from follow-on schedule check
