[2023-12-20T03:07:56.935+0000] {taskinstance.py:1957} INFO - Dependencies all met for dep_context=non-requeueable deps ti=<TaskInstance: test2.run_query manual__2023-12-20T03:07:55.162908+00:00 [queued]>
[2023-12-20T03:07:56.940+0000] {taskinstance.py:1957} INFO - Dependencies all met for dep_context=requeueable deps ti=<TaskInstance: test2.run_query manual__2023-12-20T03:07:55.162908+00:00 [queued]>
[2023-12-20T03:07:56.941+0000] {taskinstance.py:2171} INFO - Starting attempt 1 of 1
[2023-12-20T03:07:56.948+0000] {taskinstance.py:2192} INFO - Executing <Task(PythonOperator): run_query> on 2023-12-20 03:07:55.162908+00:00
[2023-12-20T03:07:56.953+0000] {standard_task_runner.py:60} INFO - Started process 5259 to run task
[2023-12-20T03:07:56.958+0000] {standard_task_runner.py:87} INFO - Running: ['***', 'tasks', 'run', 'test2', 'run_query', 'manual__2023-12-20T03:07:55.162908+00:00', '--job-id', '3', '--raw', '--subdir', 'DAGS_FOLDER/test2.py', '--cfg-path', '/tmp/tmpu7ctg2if']
[2023-12-20T03:07:56.960+0000] {standard_task_runner.py:88} INFO - Job 3: Subtask run_query
[2023-12-20T03:07:57.002+0000] {task_command.py:423} INFO - Running <TaskInstance: test2.run_query manual__2023-12-20T03:07:55.162908+00:00 [running]> on host 832c356794a0
[2023-12-20T03:07:57.049+0000] {taskinstance.py:2481} INFO - Exporting env vars: AIRFLOW_CTX_DAG_OWNER='***' AIRFLOW_CTX_DAG_ID='test2' AIRFLOW_CTX_TASK_ID='run_query' AIRFLOW_CTX_EXECUTION_DATE='2023-12-20T03:07:55.162908+00:00' AIRFLOW_CTX_TRY_NUMBER='1' AIRFLOW_CTX_DAG_RUN_ID='manual__2023-12-20T03:07:55.162908+00:00'
[2023-12-20T03:07:57.053+0000] {taskinstance.py:2699} ERROR - Task failed with exception
Traceback (most recent call last):
  File "/home/airflow/.local/lib/python3.8/site-packages/airflow/models/taskinstance.py", line 433, in _execute_task
    result = execute_callable(context=context, **execute_callable_kwargs)
  File "/home/airflow/.local/lib/python3.8/site-packages/airflow/operators/python.py", line 199, in execute
    return_value = self.execute_callable()
  File "/home/airflow/.local/lib/python3.8/site-packages/airflow/operators/python.py", line 216, in execute_callable
    return self.python_callable(*self.op_args, **self.op_kwargs)
  File "/opt/airflow/dags/test2.py", line 19, in run_query
    query = pd.read_csv(tmpl_search_path)
  File "/home/airflow/.local/lib/python3.8/site-packages/pandas/io/parsers.py", line 688, in read_csv
    return _read(filepath_or_buffer, kwds)
  File "/home/airflow/.local/lib/python3.8/site-packages/pandas/io/parsers.py", line 454, in _read
    parser = TextFileReader(fp_or_buf, **kwds)
  File "/home/airflow/.local/lib/python3.8/site-packages/pandas/io/parsers.py", line 948, in __init__
    self._make_engine(self.engine)
  File "/home/airflow/.local/lib/python3.8/site-packages/pandas/io/parsers.py", line 1180, in _make_engine
    self._engine = CParserWrapper(self.f, **self.options)
  File "/home/airflow/.local/lib/python3.8/site-packages/pandas/io/parsers.py", line 2010, in __init__
    self._reader = parsers.TextReader(src, **kwds)
  File "pandas/_libs/parsers.pyx", line 382, in pandas._libs.parsers.TextReader.__cinit__
  File "pandas/_libs/parsers.pyx", line 674, in pandas._libs.parsers.TextReader._setup_parser_source
FileNotFoundError: [Errno 2] No such file or directory: '/Users/williamlim/dev/airflow/amazon.csv'
[2023-12-20T03:07:57.063+0000] {taskinstance.py:1138} INFO - Marking task as FAILED. dag_id=test2, task_id=run_query, execution_date=20231220T030755, start_date=20231220T030756, end_date=20231220T030757
[2023-12-20T03:07:57.069+0000] {standard_task_runner.py:107} ERROR - Failed to execute job 3 for task run_query ([Errno 2] No such file or directory: '/Users/williamlim/dev/airflow/amazon.csv'; 5259)
[2023-12-20T03:07:57.090+0000] {local_task_job_runner.py:234} INFO - Task exited with return code 1
[2023-12-20T03:07:57.102+0000] {taskinstance.py:3281} INFO - 0 downstream tasks scheduled from follow-on schedule check
