[2023-12-26T00:59:58.453+0000] {taskinstance.py:1957} INFO - Dependencies all met for dep_context=non-requeueable deps ti=<TaskInstance: extract-transform-load.load manual__2023-12-26T00:59:57.369434+00:00 [queued]>
[2023-12-26T00:59:58.458+0000] {taskinstance.py:1957} INFO - Dependencies all met for dep_context=requeueable deps ti=<TaskInstance: extract-transform-load.load manual__2023-12-26T00:59:57.369434+00:00 [queued]>
[2023-12-26T00:59:58.458+0000] {taskinstance.py:2171} INFO - Starting attempt 1 of 6
[2023-12-26T00:59:58.464+0000] {taskinstance.py:2192} INFO - Executing <Task(_PythonDecoratedOperator): load> on 2023-12-26 00:59:57.369434+00:00
[2023-12-26T00:59:58.468+0000] {standard_task_runner.py:60} INFO - Started process 90 to run task
[2023-12-26T00:59:58.471+0000] {standard_task_runner.py:87} INFO - Running: ['***', 'tasks', 'run', 'extract-transform-load', 'load', 'manual__2023-12-26T00:59:57.369434+00:00', '--job-id', '125', '--raw', '--subdir', 'DAGS_FOLDER/api.py', '--cfg-path', '/tmp/tmpo401ha1c']
[2023-12-26T00:59:58.473+0000] {standard_task_runner.py:88} INFO - Job 125: Subtask load
[2023-12-26T00:59:58.505+0000] {task_command.py:423} INFO - Running <TaskInstance: extract-transform-load.load manual__2023-12-26T00:59:57.369434+00:00 [running]> on host cee0b2bde18d
[2023-12-26T00:59:58.716+0000] {taskinstance.py:2481} INFO - Exporting env vars: AIRFLOW_CTX_DAG_OWNER='william' AIRFLOW_CTX_DAG_ID='extract-transform-load' AIRFLOW_CTX_TASK_ID='load' AIRFLOW_CTX_EXECUTION_DATE='2023-12-26T00:59:57.369434+00:00' AIRFLOW_CTX_TRY_NUMBER='1' AIRFLOW_CTX_DAG_RUN_ID='manual__2023-12-26T00:59:57.369434+00:00'
[2023-12-26T00:59:58.718+0000] {taskinstance.py:2699} ERROR - Task failed with exception
Traceback (most recent call last):
  File "/home/airflow/.local/lib/python3.8/site-packages/airflow/models/taskinstance.py", line 433, in _execute_task
    result = execute_callable(context=context, **execute_callable_kwargs)
  File "/home/airflow/.local/lib/python3.8/site-packages/airflow/decorators/base.py", line 242, in execute
    return_value = super().execute(context)
  File "/home/airflow/.local/lib/python3.8/site-packages/airflow/operators/python.py", line 199, in execute
    return_value = self.execute_callable()
  File "/home/airflow/.local/lib/python3.8/site-packages/airflow/operators/python.py", line 216, in execute_callable
    return self.python_callable(*self.op_args, **self.op_kwargs)
  File "/opt/airflow/dags/api.py", line 36, in load
    connection = psycopg2.connect(user="postgres",
  File "/home/airflow/.local/lib/python3.8/site-packages/psycopg2/__init__.py", line 122, in connect
    conn = _connect(dsn, connection_factory=connection_factory, **kwasync)
psycopg2.OperationalError: connection to server at "db" (172.18.0.5), port 5433 failed: Connection refused
	Is the server running on that host and accepting TCP/IP connections?

[2023-12-26T00:59:58.728+0000] {taskinstance.py:1138} INFO - Marking task as UP_FOR_RETRY. dag_id=extract-transform-load, task_id=load, execution_date=20231226T005957, start_date=20231226T005958, end_date=20231226T005958
[2023-12-26T00:59:58.735+0000] {standard_task_runner.py:107} ERROR - Failed to execute job 125 for task load (connection to server at "db" (172.18.0.5), port 5433 failed: Connection refused
	Is the server running on that host and accepting TCP/IP connections?
; 90)
[2023-12-26T00:59:58.767+0000] {local_task_job_runner.py:234} INFO - Task exited with return code 1
[2023-12-26T00:59:58.780+0000] {taskinstance.py:3281} INFO - 0 downstream tasks scheduled from follow-on schedule check
